## Prompts (Powered by Gemini 2.5 Pro)
### Question)
```
Use GPU: cuda:0

Traceback (most recent call last):

  File "/hdd/intern/aLLM4TS/run_LLM4TS.py", line 180, in <module>

    exp = Exp(args)

  File "/hdd/intern/aLLM4TS/exp/exp_LLM4TS.py", line 28, in __init__

    super(Exp_Main, self).__init__(args)

  File "/hdd/intern/aLLM4TS/exp/exp_basic.py", line 16, in __init__

    self.model = self._build_model().to(self.device)

  File "/hdd/intern/aLLM4TS/exp/exp_LLM4TS.py", line 35, in _build_model

    model = model_dict[self.args.model].Model(self.args).float()

  File "/hdd/intern/aLLM4TS/models/LLM4TS_pt.py", line 32, in __init__

    self.gpt = GPT2Model.from_pretrained(configs.llm, output_attentions=True, output_hidden_states=True)

  File "/hdd/conda_envs/envs/aLLM4TS/lib/python3.10/site-packages/transformers/modeling_utils.py", line 2507, in from_pretrained

    resolved_config_file = cached_file(

  File "/hdd/conda_envs/envs/aLLM4TS/lib/python3.10/site-packages/transformers/utils/hub.py", line 429, in cached_file

    resolved_file = hf_hub_download(

  File "/hdd/conda_envs/envs/aLLM4TS/lib/python3.10/site-packages/huggingface_hub/utils/_validators.py", line 110, in _inner_fn

    validate_repo_id(arg_value)

  File "/hdd/conda_envs/envs/aLLM4TS/lib/python3.10/site-packages/huggingface_hub/utils/_validators.py", line 158, in validate_repo_id

    raise HFValidationError(

huggingface_hub.utils._validators.HFValidationError: Repo id must be in the form 'repo_name' or 'namespace/repo_name': './hf_models/gpt2'. Use `repo_type` argument if needed.
```
### Answer)
이 오류는 Hugging Face transformers 라이브러리가 사전 학습된 모델을 로드하려고 할 때, 모델의 경로를 잘못 해석해서 발생합니다.

간단히 말해, 코드에서 './hf_models/gpt2'라는 로컬 경로를 지정했지만, 라이브러리는 이것을 유효하지 않은 Hugging Face Hub 모델 ID로 인식하고 오류를 일으킨 것입니다.

## 문제의 원인 🧐
transformers 라이브러리의 from_pretrained 함수는 똑똑해서, 주어진 문자열이 로컬에 존재하는 폴더 경로이면 해당 폴더에서 모델을 로드하고, 그렇지 않으면 Hugging Face Hub (온라인 저장소)에서 모델을 다운로드하려고 시도합니다.

오류 메시지 Repo id must be in the form 'repo_name' or 'namespace/repo_name'는 라이브러리가 './hf_models/gpt2'를 Hub ID로 해석했으나, 형식(.이나 /로 시작)이 맞지 않아 발생한 것입니다. 이는 다음 두 가지 중 하나를 의미합니다.

경로가 잘못되었습니다. 스크립트를 실행하는 위치 기준으로 './hf_models/gpt2' 폴더가 실제로 존재하지 않습니다.

원래 의도는 Hub에서 다운로드하는 것이었습니다. 로컬 경로가 아닌 gpt2라는 이름의 모델을 Hub에서 다운로드하려고 했을 수 있습니다.

## 해결 방법 💡
가장 가능성이 높은 원인부터 순서대로 확인해 보세요.

1. 로컬 경로 확인 및 절대 경로 사용 (가장 가능성 높은 해결책)
스크립트를 실행하는 위치에 './hf_models/gpt2' 폴더가 있는지 확인하는 것이 가장 중요합니다.

현재 위치 확인: 터미널에서 run_LLM4TS.py 스크립트를 실행한 폴더가 /hdd/intern/aLLM4TS/가 맞는지 확인합니다.

폴더 존재 여부 확인: 해당 위치에서 아래 명령어를 실행하여 폴더와 그 안의 파일들을 확인해 보세요.

Bash

ls -l /hdd/intern/aLLM4TS/hf_models/gpt2/
성공적으로 모델이 다운로드되었다면 config.json, pytorch_model.bin 같은 파일들이 보여야 합니다.

해결책: 절대 경로 사용
경로 문제로 인한 혼동을 피하기 위해, 설정 파일이나 코드에서 절대 경로를 사용하는 것이 가장 확실합니다.
'./hf_models/gpt2' 대신 아래와 같이 전체 경로를 사용하도록 코드를 수정하세요.

Python

# 수정 전
# configs.llm = './hf_models/gpt2'

# 수정 후
configs.llm = '/hdd/intern/aLLM4TS/hf_models/gpt2'
2. 모델을 Hugging Face Hub에서 직접 다운로드
만약 로컬에 모델을 미리 다운로드해 둔 것이 아니라, 코드를 실행할 때 인터넷을 통해 다운로드하려는 의도였다면, 경로를 모델의 공식 ID인 'gpt2'로 변경해야 합니다.

해결책: 모델 ID 사용
설정 파일이나 코드에서 configs.llm 값을 다음과 같이 수정하세요.

Python

# 수정 전
# configs.llm = './hf_models/gpt2'

# 수정 후
configs.llm = 'gpt2'
이렇게 하면 transformers 라이브러리가 Hugging Face Hub에서 gpt2 모델을 자동으로 다운로드하여 캐시 폴더에 저장하고 로드합니다.

## 요약
로컬에 모델이 있다면 → 경로를 './hf_models/gpt2'에서 절대 경로인 '/hdd/intern/aLLM4TS/hf_models/gpt2'로 변경하세요.

로컬에 모델이 없고 다운로드할 생각이었다면 → 경로를 모델 ID인 'gpt2'로 변경하세요.

---

### Question)
```
Setting ds_accelerator to cuda (auto detect)

Use GPU: cuda:0

Traceback (most recent call last):

  File "/hdd/intern/aLLM4TS/run_LLM4TS.py", line 180, in <module>

    exp = Exp(args)

  File "/hdd/intern/aLLM4TS/exp/exp_LLM4TS.py", line 28, in __init__

    super(Exp_Main, self).__init__(args)

  File "/hdd/intern/aLLM4TS/exp/exp_basic.py", line 16, in __init__

    self.model = self._build_model().to(self.device)

  File "/hdd/intern/aLLM4TS/exp/exp_LLM4TS.py", line 35, in _build_model

    model = model_dict[self.args.model].Model(self.args).float()

  File "/hdd/intern/aLLM4TS/models/LLM4TS_pt.py", line 32, in __init__

    self.gpt = GPT2Model.from_pretrained(configs.llm, output_attentions=True, output_hidden_states=True)

  File "/hdd/conda_envs/envs/aLLM4TS/lib/python3.10/site-packages/transformers/modeling_utils.py", line 2662, in from_pretrained

    config, model_kwargs = cls.config_class.from_pretrained(

  File "/hdd/conda_envs/envs/aLLM4TS/lib/python3.10/site-packages/transformers/configuration_utils.py", line 591, in from_pretrained

    config_dict, kwargs = cls.get_config_dict(pretrained_model_name_or_path, **kwargs)

  File "/hdd/conda_envs/envs/aLLM4TS/lib/python3.10/site-packages/transformers/configuration_utils.py", line 620, in get_config_dict

    config_dict, kwargs = cls._get_config_dict(pretrained_model_name_or_path, **kwargs)

  File "/hdd/conda_envs/envs/aLLM4TS/lib/python3.10/site-packages/transformers/configuration_utils.py", line 675, in _get_config_dict

    resolved_config_file = cached_file(

  File "/hdd/conda_envs/envs/aLLM4TS/lib/python3.10/site-packages/transformers/utils/hub.py", line 400, in cached_file

    raise EnvironmentError(

OSError: ./hf_models/gpt2 does not appear to have a file named config.json. Checkout 'https://huggingface.co/./hf_models/gpt2/main' for available files.
```
### Answer)
이전 오류(HFValidationError)는 경로의 형식 문제였고, 이번 OSError는 경로 내용의 문제입니다.

오류 메시지를 직역하면 이렇습니다: "./hf_models/gpt2 폴더를 찾아갔는데, 그 안에 config.json 파일이 없습니다."

## 문제의 원인 🧐
Hugging Face transformers 라이브러리는 모델을 로드할 때 두 가지 핵심 파일을 필요로 합니다.

config.json: 모델의 구조(레이어 수, 히든 사이즈 등)가 정의된 설계도 파일입니다.

pytorch_model.bin (또는 비슷한 이름): 실제 학습된 가중치(weights)가 저장된 모델 파라미터 파일입니다.

from_pretrained 함수는 가장 먼저 config.json을 읽어서 모델의 뼈대를 만든 후, pytorch_model.bin 파일에서 가중치를 가져와 채워 넣습니다.

따라서, OSError: ... does not appear to have a file named config.json 오류는 지정된 경로에 모델의 설계도 파일이 없어서 모델을 어떻게 만들어야 할지 모를 때 발생합니다. 즉, 모델 파일이 없거나 불완전하게 다운로드된 것입니다.

## 해결 방법 💡
가장 확실한 해결책은 해당 경로에 올바른 모델 파일들을 다운로드하여 저장하는 것입니다.

1. 모델 파일 다운로드 및 저장 스크립트 실행
프로젝트의 루트 디렉터리(/hdd/intern/aLLM4TS/)에 download_model.py와 같은 간단한 파이썬 스크립트 파일을 하나 만드세요. 그리고 아래 내용을 붙여넣으세요.

Python

from transformers import GPT2Model, GPT2Config

# 다운로드할 모델 이름
model_name = 'gpt2'

# 저장할 로컬 경로 (오류 메시지에 나온 경로와 동일하게)
save_directory = './hf_models/gpt2' 

# 모델과 설정을 다운로드
print(f"'{model_name}' 모델을 다운로드하여 '{save_directory}'에 저장합니다...")
model = GPT2Model.from_pretrained(model_name)
config = GPT2Config.from_pretrained(model_name)

# 지정된 경로에 파일들을 저장
model.save_pretrained(save_directory)
config.save_pretrained(save_directory)

print("다운로드 및 저장이 완료되었습니다!")
2. 스크립트 실행
터미널에서 프로젝트의 가상 환경을 활성화한 후, 이 스크립트를 실행합니다.

Bash

# aLLM4TS 가상 환경 활성화
conda activate aLLM4TS 

# 프로젝트 루트 디렉터리로 이동
cd /hdd/intern/aLLM4TS

# 다운로드 스크립트 실행
python download_model.py
이 스크립트는 Hugging Face Hub에서 gpt2 모델의 config.json, pytorch_model.bin 등 필요한 모든 파일을 다운로드하여 ./hf_models/gpt2/ 폴더 안에 저장해 줄 것입니다.

3. 확인 및 재실행
스크립트 실행이 완료된 후, 폴더 내용을 확인해 보세요.

Bash

ls -l /hdd/intern/aLLM4TS/hf_models/gpt2/
이제 config.json과 pytorch_model.bin 파일이 보일 것입니다. 이 상태에서 원래 실행하려던 run_LLM4TS.py 스크립트를 다시 실행하면 정상적으로 모델을 로드할 것입니다.

## 요약
문제: 코드가 모델을 로드하려는 폴더 (./hf_models/gpt2/)에 설정 파일(config.json)이 없습니다.

해결책: 위에서 제공한 파이썬 스크립트를 실행하여 gpt2 모델의 전체 파일을 해당 폴더에 다운로드하고 저장하세요.