## Prompts (Powered by Gemini 2.5 Pro)
### Question)
```
Traceback (most recent call last):

  File "store_emb.py", line 92, in <module>

    save_embeddings(args)

  File "store_emb.py", line 72, in save_embeddings

    embeddings = gen_prompt_emb.generate_embeddings(x.to(device), y.to(device), x_mark.to(device), y_mark.to(device))

  File "/home/intern/z_timeKD/clm.py", line 329, in generate_embeddings

    sub_out = self.sub_ac(prompt_emb_GT_1, prompt_emb_HD_1, prompt_emb_HD_1)

  File "/usr/local/lib/python3.8/dist-packages/torch/nn/modules/module.py", line 1553, in _wrapped_call_impl

    return self._call_impl(*args, **kwargs)

  File "/usr/local/lib/python3.8/dist-packages/torch/nn/modules/module.py", line 1562, in _call_impl

    return forward_call(*args, **kwargs)

  File "/home/intern/z_timeKD/layers/Sub_CA.py", line 26, in forward

    for mod in self.layers: output, scores = mod(q,k,v,  prev=scores, key_padding_mask=key_padding_mask, attn_mask=attn_mask)

  File "/usr/local/lib/python3.8/dist-packages/torch/nn/modules/module.py", line 1553, in _wrapped_call_impl

    return self._call_impl(*args, **kwargs)

  File "/usr/local/lib/python3.8/dist-packages/torch/nn/modules/module.py", line 1562, in _call_impl

    return forward_call(*args, **kwargs)

  File "/home/intern/z_timeKD/layers/Sub_CA.py", line 63, in forward

    q = self.norm_attn(q)

  File "/usr/local/lib/python3.8/dist-packages/torch/nn/modules/module.py", line 1553, in _wrapped_call_impl

    return self._call_impl(*args, **kwargs)

  File "/usr/local/lib/python3.8/dist-packages/torch/nn/modules/module.py", line 1562, in _call_impl

    return forward_call(*args, **kwargs)

  File "/usr/local/lib/python3.8/dist-packages/torch/nn/modules/normalization.py", line 202, in forward

    return F.layer_norm(

  File "/usr/local/lib/python3.8/dist-packages/torch/nn/functional.py", line 2576, in layer_norm

    return torch.layer_norm(input, normalized_shape, weight, bias, eps, torch.backends.cudnn.enabled)

RuntimeError: Given normalized_shape=[7], expected input with shape [*, 7], but got input of size[1, 768, 21]

Traceback (most recent call last):

  File "store_emb.py", line 92, in <module>

    save_embeddings(args)

  File "store_emb.py", line 72, in save_embeddings

    embeddings = gen_prompt_emb.generate_embeddings(x.to(device), y.to(device), x_mark.to(device), y_mark.to(device))

  File "/home/intern/z_timeKD/clm.py", line 329, in generate_embeddings

    sub_out = self.sub_ac(prompt_emb_GT_1, prompt_emb_HD_1, prompt_emb_HD_1)

  File "/usr/local/lib/python3.8/dist-packages/torch/nn/modules/module.py", line 1553, in _wrapped_call_impl

    return self._call_impl(*args, **kwargs)

  File "/usr/local/lib/python3.8/dist-packages/torch/nn/modules/module.py", line 1562, in _call_impl

    return forward_call(*args, **kwargs)

  File "/home/intern/z_timeKD/layers/Sub_CA.py", line 26, in forward

    for mod in self.layers: output, scores = mod(q,k,v,  prev=scores, key_padding_mask=key_padding_mask, attn_mask=attn_mask)

  File "/usr/local/lib/python3.8/dist-packages/torch/nn/modules/module.py", line 1553, in _wrapped_call_impl

    return self._call_impl(*args, **kwargs)

  File "/usr/local/lib/python3.8/dist-packages/torch/nn/modules/module.py", line 1562, in _call_impl

    return forward_call(*args, **kwargs)

  File "/home/intern/z_timeKD/layers/Sub_CA.py", line 63, in forward

    q = self.norm_attn(q)

  File "/usr/local/lib/python3.8/dist-packages/torch/nn/modules/module.py", line 1553, in _wrapped_call_impl

    return self._call_impl(*args, **kwargs)

  File "/usr/local/lib/python3.8/dist-packages/torch/nn/modules/module.py", line 1562, in _call_impl

    return forward_call(*args, **kwargs)

  File "/usr/local/lib/python3.8/dist-packages/torch/nn/modules/normalization.py", line 202, in forward

    return F.layer_norm(

  File "/usr/local/lib/python3.8/dist-packages/torch/nn/functional.py", line 2576, in layer_norm

    return torch.layer_norm(input, normalized_shape, weight, bias, eps, torch.backends.cudnn.enabled)

RuntimeError: Given normalized_shape=[7], expected input with shape [*, 7], but got input of size[1, 768, 21]



이 에러는 뭐지? 참고로, dataset 포맷은 다음과 같아.



date,p (mbar),T (degC),Tpot (K),Tdew (degC),rh (%),VPmax (mbar),VPact (mbar),VPdef (mbar),sh (g/kg),H2OC (mmol/mol),rho (g/m**3),wv (m/s),max. wv (m/s),wd (deg),rain (mm),raining (s),SWDR (W/m ),PAR ( mol/m /s),max. PAR ( mol/m /s),Tlog (degC),OT

2020-01-01 00:10:00,1008.89,0.71,273.18,-1.33,86.1,6.43,5.54,0.89,3.42,5.49,1280.62,1.02,1.6,224.3,0.0,0.0,0.0,0.0,0.0,11.45,428.1
```

### Answer)
이 에러는 PyTorch LayerNorm 계층의 설정값과 실제 입력 데이터의 차원(크기)이 맞지 않아서 발생하는 문제입니다. 제공해주신 데이터셋 정보를 보니 원인이 명확해 보입니다.

## 에러 상세 분석
에러 메시지를 다시 살펴보겠습니다.

RuntimeError: Given normalized_shape=[7], ... but got input of size[1, 768, 21]

이 메시지는 LayerNorm 계층이 마지막 차원 크기를 7로 예상했는데, 실제로는 크기가 21인 텐서가 입력되었다는 뜻입니다.

예상: 텐서 모양 [배치 크기, 시퀀스 길이, **피처 개수=7**]

실제: 텐서 모양 [1, 768, **피처 개수=21**]

## 원인: 데이터셋과 모델 설정의 불일치
가장 유력한 원인은 모델이 7개의 변수(피처)를 가진 데이터셋을 기준으로 설정되어 있기 때문입니다.

데이터셋 분석: 보내주신 데이터셋의 헤더를 보면 date를 제외하고 p (mbar)부터 OT까지 22개의 변수가 있습니다. 여기서 하나를 타겟 변수로 사용하면 입력 피처의 개수는 21개가 됩니다.

모델 입력: 에러 메시지에 나온 실제 입력 텐서의 크기 [1, 768, 21]을 보면, 모델이 데이터셋의 21개 피처를 정상적으로 입력받고 있음을 알 수 있습니다.

결론: 문제는 데이터가 아니라 모델의 설정값에 있습니다. 현재 사용 중인 모델 코드는 기본값이 7개 피처를 가진 데이터셋(예: ETTh1, ETTm1 등 유명 벤치마크 데이터셋)에 맞춰져 있을 가능성이 매우 높습니다. 하지만 지금은 21개의 피처를 가진 새로운 데이터셋을 사용하고 있으므로 이 설정값을 바꿔줘야 합니다.

## 해결 방안
모델을 실행하는 스크립트나 설정 파일에서 입력 피처의 개수를 지정하는 파라미터를 찾아서 값을 7에서 21로 변경해야 합니다.

보통 아래와 같은 이름의 인자(argument)로 설정되어 있습니다.

--c_in

--enc_in

--dec_in

--n_features

--input_dim

예를 들어, 터미널에서 실행하는 스크립트라면 실행 명령어에 아래와 같이 옵션을 추가하거나,

Bash

python store_emb.py --enc_in 21 --dec_in 21 ... # 다른 인자들
스크립트 내의 argparse 기본값을 수정해야 합니다.

Python

# store_emb.py 또는 관련 설정 파일 내부
parser = argparse.ArgumentParser(description='...')
# 이 부분의 default 값을 7에서 21로 수정하세요.
parser.add_argument('--enc_in', type=int, default=21, help='encoder input size')
parser.add_argument('--dec_in', type=int, default=21, help='decoder input size')
이 값을 21로 수정하면 LayerNorm을 포함한 모델의 모든 계층이 새로운 데이터셋의 차원 수에 맞게 초기화되어 에러가 해결될 것입니다. ✅

---

### Question)
```
그런데,

date,HUFL,HULL,MUFL,MULL,LUFL,LULL,OT

포맷이 이러한 데이터셋에서는 문제 없이 수행되었어. Date 는 제외하는건가?
```

### Answer)
네, 정확히 보셨습니다! 이전 데이터셋에서 문제없이 실행된 이유는 바로 변수(피처)의 개수가 7개였기 때문입니다. 이것이 바로 에러의 원인을 확실하게 뒷받침하는 증거입니다.

그리고 질문하신 대로, date는 일반적으로 모델의 입력 피처로 계산하지 않고 데이터의 순서를 나타내는 **인덱스(index)**로 사용됩니다.

## 두 데이터셋의 결정적 차이
두 경우를 비교해 보면 모든 것이 명확해집니다.

1. 정상 작동한 데이터셋 (HUFL, HULL, ...)
컬럼: date, HUFL, HULL, MUFL, MULL, LUFL, LULL, OT

date를 제외한 실제 입력 피처 개수: 7개

이 숫자 7은 원래 에러 메시지에 나왔던 모델이 기대하던 normalized_shape=[7]과 정확히 일치합니다. 모델의 설정값과 데이터의 피처 개수가 같았기 때문에 아무 문제 없이 작동한 것입니다.

2. 에러가 발생한 데이터셋 (p (mbar), T (degC), ...)
date를 제외한 실제 입력 피처 개수: 21개

모델은 7개의 피처를 처리하도록 설정되어 있는데, 21개의 피처가 들어오니 차원(shape)이 맞지 않아 RuntimeError가 발생한 것입니다.

## 결론
결론적으로, 모델 코드 자체에는 문제가 없고 모델의 입력 피처 개수 설정(enc_in, c_in 등)이 특정 데이터셋(7개 피처)에 맞게 고정되어 있었던 것이 원인입니다. 👍

따라서 이전에 말씀드린 해결책대로, 현재 사용하시는 21개 피처 데이터셋에 맞게 모델의 입력 피처 개수 파라미터 값을 21로 변경해주시면 문제가 해결됩니다.
